Workbook

Sheet Accueil
B1: Base de données des pubs de jeux vidéo dans les magazines
B4: Comment c'est organisé
B5: Plateformes | C5: Liste des consoles / machines (déjà pré-remplie, complétez si besoin).
B6: Séries | C6: Liste des séries de jeux (Final Fantasy, Dragon Quest...).
B7: Magazines | C7: Liste des magazines (Famitsu, Dengeki PlayStation...).
B8: Numéros | C8: Facultatif : un numéro par ligne avec sa date de parution. Sert à dater les pubs et à chercher par année.
B9: Jeux | C9: Un jeu par ligne : titre, série, éditeur, année. Les compteurs (nb de pubs, d'apparitions...) sont calculés.
B10: Pubs | C10: Un visuel publicitaire par ligne, avec un ID unique. Un même jeu peut avoir plusieurs pubs (visuels différents).
B11: Apparitions | C11: LE carnet de saisie : une ligne = une pub trouvée dans un numéro de magazine (magazine, n°, page, pub, en vente ○/×).
B12: Recherche | C12: Recherche croisée : pubs d'un numéro, parutions d'un jeu ou d'une pub, par série, plateforme, année, en vente...
B14: Saisie au quotidien
B15: 1. Nouveau jeu ? | C15: L'ajouter dans Jeux (et sa série dans Séries si elle n'existe pas).
B16: 2. Nouvelle pub ? | C16: L'ajouter dans Pubs avec le « Prochain ID libre » affiché en haut à droite de l'onglet, et une description qui permet de la reconnaître.
B17: 3. Chaque pub trouvée | C17: Une ligne dans Apparitions : choisir le magazine, taper le numéro et la page, choisir la pub dans la liste (on peut taper le début du nom du jeu ou juste l'ID), puis ○ ou ×.
B18: Astuce | C18: Pour enchaîner les pubs d'un même numéro : Ctrl+D recopie la cellule du dessus (magazine, numéro).
B20: Codes couleur
B21: En-tête jaune | C21: Colonne à remplir à la main.
B22: En-tête / cellules grises | C22: Calculé automatiquement : ne pas modifier.
B23: Rouge | C23: Doublon (nom ou ID déjà utilisé) ou ×.
B24: Orange | C24: Pub / jeu inconnu, ou même magazine + n° + page saisi deux fois.
B26: Bon à savoir
B27: Données d'exemple | C27: Les lignes marquées « EXEMPLE » (Numéros, Jeux, Pubs, Apparitions) sont fictives : sélectionnez-les, clic droit > Supprimer.
B28: Filtres et tris | C28: Chaque onglet a des filtres (flèches dans l'en-tête) : trier les jeux par nb d'apparitions, filtrer les pubs d'un jeu, etc.
B29: Faire évoluer | C29: On peut ajouter des colonnes à droite de chaque onglet (format, état, prix...). Ne pas renommer les onglets ni supprimer les colonnes grises.
B30: Capacité | C30: Lignes préparées : 5000 apparitions, 3000 pubs, 3000 jeux. Au-delà, recopier la dernière ligne vers le bas.
B31: Renommer un jeu | C31: Si on corrige le titre d'un jeu dans Jeux, le corriger aussi dans Pubs (Rechercher/Remplacer).
B32: Compatibilité | C32: Excel 2010 et plus, LibreOffice. La « 1re parution » demande Excel 2019 / Microsoft 365 (sinon la colonne reste vide).
B34: Chiffres clés
B35: Apparitions | C35: =COUNTIF(Apparitions!$A$2:$A$5001,"?*") -> 8
B36: Pubs différentes | C36: =COUNT(Pubs!$A$2:$A$3001) -> 5
B37: Jeux | C37: =SUMPRODUCT(--(LEN(Jeux!$A$2:$A$3001)>0)) -> 4
B38: Séries | C38: =SUMPRODUCT(--(LEN(Séries!$A$2:$A$1001)>0)) -> 4
B39: Magazines | C39: =SUMPRODUCT(--(LEN(Magazines!$A$2:$A$301)>0)) -> 3
B40: Numéros répertoriés | C40: =SUMPRODUCT(--(LEN(Numéros!$A$2:$A$3001)>0)) -> 5
B41: Apparitions en vente (○) | C41: =COUNTIF(Apparitions!$E$2:$E$5001,"○") -> 4
B42: Prochain ID de pub libre | C42: =MAX(Pubs!$A$2:$A$3001)+1 -> 6

Sheet Recherche
B1: Recherche croisée
B2: Remplissez un ou plusieurs critères (cases jaunes) : les résultats se mettent à jour tout seuls. Critère vide = ignoré. Tous les critères remplis doivent être vrais.
B3: Critère | C3: Valeur | D3: Aide | J3: Synthèse
B4: Magazine | D4: Liste déroulante | J4: Apparitions trouvées | K4: =MAX(Apparitions!$N$1:$N$5001) -> 8
B5: Numéro | D5: Exact (ex. 425) | J5: Pubs différentes | K5: =SUM(O16:O515) -> 5
B6: Année de parution | D6: Ex. 1997 (nécessite la date dans Numéros) | J6: Jeux différents | K6: =SUM(P16:P515) -> 4
B7: Jeu (contient) | D7: Ex. « Final » trouve tous les Final Fantasy | J7: Numéros différents | K7: =SUM(R16:R515) -> 6
B8: Série | D8: Liste déroulante | J8: Dont en vente (○) | K8: =COUNTIF(L16:L515,"○") -> 4
B9: Plateforme | D9: Liste déroulante | J9: Total pages de pub | K9: =SUM(K16:K515) -> 13
B10: ID pub | D10: Toutes les parutions d'une même pub
B11: En vente (○ / ×) | D11: Liste déroulante | J11: =IF(K4>500,"⚠ Seuls les 500 premiers résultats sont affichés : affinez la recherche.","")
B12: Mot-clé | D12: Cherché dans la description de la pub et les remarques
B13: Astuce : pour trouver toutes les parutions d'une pub précise, mettez juste son ID. Pour la liste des pubs d'un numéro : Magazine + Numéro.
A15: (ligne) | B15: Magazine | C15: N° | D15: Date | E15: Page | F15: Jeu | G15: Plateforme | H15: Série | I15: ID pub | J15: Description pub | K15: Nb p. | L15: En vente | M15: Remarques
A16: =IFERROR(MATCH(1,Apparitions!$N$1:$N$5001,0),"") -> 2 | B16: =IF($A16="","",INDEX(Apparitions!$A$1:$A$5001,$A16)&"") -> Weekly Famitsu | C16: =IF($A16="","",INDEX(Apparitions!$B$1:$B$5001,$A16)&"") -> 421 | D16: =IF($A16="","",INDEX(Apparitions!$L$1:$L$5001,$A16)) -> 35433 | E16: =IF($A16="","",INDEX(Apparitions!$C$1:$C$5001,$A16)&"") -> 12 | F16: =IF($A16="","",INDEX(Apparitions!$H$1:$H$5001,$A16)&"") -> Final Fantasy VII | G16: =IF($A16="","",INDEX(Apparitions!$I$1:$I$5001,$A16)&"") -> PlayStation | H16: =IF($A16="","",INDEX(Apparitions!$J$1:$J$5001,$A16)&"") -> Final Fantasy | I16: =IF($A16="","",INDEX(Apparitions!$G$1:$G$5001,$A16)&"") -> 1 | J16: =IF($A16="","",INDEX(Apparitions!$M$1:$M$5001,$A16)&"") -> Cloud devant Midgar | K16: =IF($A16="","",INDEX(Apparitions!$K$1:$K$5001,$A16)) -> 2 | L16: =IF($A16="","",INDEX(Apparitions!$E$1:$E$5001,$A16)&"") -> ○ | M16: =IF($A16="","",INDEX(Apparitions!$F$1:$F$5001,$A16)&"") -> EXEMPLE - à supprimer | O16: =IF(I16="",0,IF(COUNTIF(I$16:I16,I16)=1,1,0)) -> 1 | P16: =IF(F16="",0,IF(COUNTIF(F$16:F16,F16)=1,1,0)) -> 1 | Q16: =IF(B16="","",B16&"|"&C16) -> Weekly Famitsu|421 | R16: =IF(Q16="",0,IF(COUNTIF(Q$16:Q16,Q16)=1,1,0)) -> 1
A17: =IFERROR(MATCH(2,Apparitions!$N$1:$N$5001,0),"") -> 3 | B17: =IF($A17="","",INDEX(Apparitions!$A$1:$A$5001,$A17)&"") -> Weekly Famitsu | C17: =IF($A17="","",INDEX(Apparitions!$B$1:$B$5001,$A17)&"") -> 421 | D17: =IF($A17="","",INDEX(Apparitions!$L$1:$L$5001,$A17)) -> 35433 | E17: =IF($A17="","",INDEX(Apparitions!$C$1:$C$5001,$A17)&"") -> 40 | F17: =IF($A17="","",INDEX(Apparitions!$H$1:$H$5001,$A17)&"") -> Sakura Taisen | G17: =IF($A17="","",INDEX(Apparitions!$I$1:$I$5001,$A17)&"") -> Sega Saturn | H17: =IF($A17="","",INDEX(Apparitions!$J$1:$J$5001,$A17)&"") -> Sakura Taisen | I17: =IF($A17="","",INDEX(Apparitions!$G$1:$G$5001,$A17)&"") -> 4 | J17: =IF($A17="","",INDEX(Apparitions!$M$1:$M$5001,$A17)&"") -> Sakura au sabre | K17: =IF($A17="","",INDEX(Apparitions!$K$1:$K$5001,$A17)) -> 1 | L17: =IF($A17="","",INDEX(Apparitions!$E$1:$E$5001,$A17)&"") -> × | M17: =IF($A17="","",INDEX(Apparitions!$F$1:$F$5001,$A17)&"") -> EXEMPLE - à supprimer | O17: =IF(I17="",0,IF(COUNTIF(I$16:I17,I17)=1,1,0)) -> 1 | P17: =IF(F17="",0,IF(COUNTIF(F$16:F17,F17)=1,1,0)) -> 1 | Q17: =IF(B17="","",B17&"|"&C17) -> Weekly Famitsu|421 | R17: =IF(Q17="",0,IF(COUNTIF(Q$16:Q17,Q17)=1,1,0)) -> 0
A18: =IFERROR(MATCH(3,Apparitions!$N$1:$N$5001,0),"") -> 4 | B18: =IF($A18="","",INDEX(Apparitions!$A$1:$A$5001,$A18)&"") -> Weekly Famitsu | C18: =IF($A18="","",INDEX(Apparitions!$B$1:$B$5001,$A18)&"") -> 425 | D18: =IF($A18="","",INDEX(Apparitions!$L$1:$L$5001,$A18)) -> 35461 | E18: =IF($A18="","",INDEX(Apparitions!$C$1:$C$5001,$A18)&"") -> 8 | F18: =IF($A18="","",INDEX(Apparitions!$H$1:$H$5001,$A18)&"") -> Final Fantasy VII | G18: =IF($A18="","",INDEX(Apparitions!$I$1:$I$5001,$A18)&"") -> PlayStation | H18: =IF($A18="","",INDEX(Apparitions!$J$1:$J$5001,$A18)&"") -> Final Fantasy | I18: =IF($A18="","",INDEX(Apparitions!$G$1:$G$5001,$A18)&"") -> 1 | J18: =IF($A18="","",INDEX(Apparitions!$M$1:$M$5001,$A18)&"") -> Cloud devant Midgar | K18: =IF($A18="","",INDEX(Apparitions!$K$1:$K$5001,$A18)) -> 2 | L18: =IF($A18="","",INDEX(Apparitions!$E$1:$E$5001,$A18)&"") -> × | M18: =IF($A18="","",INDEX(Apparitions!$F$1:$F$5001,$A18)&"") -> EXEMPLE - à supprimer | O18: =IF(I18="",0,IF(COUNTIF(I$16:I18,I18)=1,1,0)) -> 0 | P18: =IF(F18="",0,IF(COUNTIF(F$16:F18,F18)=1,1,0)) -> 0 | Q18: =IF(B18="","",B18&"|"&C18) -> Weekly Famitsu|425 | R18: =IF(Q18="",0,IF(COUNTIF(Q$16:Q18,Q18)=1,1,0)) -> 1
A19: =IFERROR(MATCH(4,Apparitions!$N$1:$N$5001,0),"") -> 5 | B19: =IF($A19="","",INDEX(Apparitions!$A$1:$A$5001,$A19)&"") -> Weekly Famitsu | C19: =IF($A19="","",INDEX(Apparitions!$B$1:$B$5001,$A19)&"") -> 430 | D19: =IF($A19="","",INDEX(Apparitions!$L$1:$L$5001,$A19)) -> 35496 | E19: =IF($A19="","",INDEX(Apparitions!$C$1:$C$5001,$A19)&"") -> 2 | F19: =IF($A19="","",INDEX(Apparitions!$H$1:$H$5001,$A19)&"") -> Final Fantasy VII | G19: =IF($A19="","",INDEX(Apparitions!$I$1:$I$5001,$A19)&"") -> PlayStation | H19: =IF($A19="","",INDEX(Apparitions!$J$1:$J$5001,$A19)&"") -> Final Fantasy | I19: =IF($A19="","",INDEX(Apparitions!$G$1:$G$5001,$A19)&"") -> 2 | J19: =IF($A19="","",INDEX(Apparitions!$M$1:$M$5001,$A19)&"") -> Aerith, fond fleurs | K19: =IF($A19="","",INDEX(Apparitions!$K$1:$K$5001,$A19)) -> 1 | L19: =IF($A19="","",INDEX(Apparitions!$E$1:$E$5001,$A19)&"") -> ○ | M19: =IF($A19="","",INDEX(Apparitions!$F$1:$F$5001,$A19)&"") -> EXEMPLE - à supprimer | O19: =IF(I19="",0,IF(COUNTIF(I$16:I19,I19)=1,1,0)) -> 1 | P19: =IF(F19="",0,IF(COUNTIF(F$16:F19,F19)=1,1,0)) -> 0 | Q19: =IF(B19="","",B19&"|"&C19) -> Weekly Famitsu|430 | R19: =IF(Q19="",0,IF(COUNTIF(Q$16:Q19,Q19)=1,1,0)) -> 1
A20: =IFERROR(MATCH(5,Apparitions!$N$1:$N$5001,0),"") -> 6 | B20: =IF($A20="","",INDEX(Apparitions!$A$1:$A$5001,$A20)&"") -> Dengeki PlayStation | C20: =IF($A20="","",INDEX(Apparitions!$B$1:$B$5001,$A20)&"") -> 38 | D20: =IF($A20="","",INDEX(Apparitions!$L$1:$L$5001,$A20)) -> 35440 | E20: =IF($A20="","",INDEX(Apparitions!$C$1:$C$5001,$A20)&"") -> 2 | F20: =IF($A20="","",INDEX(Apparitions!$H$1:$H$5001,$A20)&"") -> Final Fantasy VII | G20: =IF($A20="","",INDEX(Apparitions!$I$1:$I$5001,$A20)&"") -> PlayStation | H20: =IF($A20="","",INDEX(Apparitions!$J$1:$J$5001,$A20)&"") -> Final Fantasy | I20: =IF($A20="","",INDEX(Apparitions!$G$1:$G$5001,$A20)&"") -> 1 | J20: =IF($A20="","",INDEX(Apparitions!$M$1:$M$5001,$A20)&"") -> Cloud devant Midgar | K20: =IF($A20="","",INDEX(Apparitions!$K$1:$K$5001,$A20)) -> 2 | L20: =IF($A20="","",INDEX(Apparitions!$E$1:$E$5001,$A20)&"") -> ○ | M20: =IF($A20="","",INDEX(Apparitions!$F$1:$F$5001,$A20)&"") -> EXEMPLE - à supprimer | O20: =IF(I20="",0,IF(COUNTIF(I$16:I20,I20)=1,1,0)) -> 0 | P20: =IF(F20="",0,IF(COUNTIF(F$16:F20,F20)=1,1,0)) -> 0 | Q20: =IF(B20="","",B20&"|"&C20) -> Dengeki PlayStation|38 | R20: =IF(Q20="",0,IF(COUNTIF(Q$16:Q20,Q20)=1,1,0)) -> 1
A21: =IFERROR(MATCH(6,Apparitions!$N$1:$N$5001,0),"") -> 7 | B21: =IF($A21="","",INDEX(Apparitions!$A$1:$A$5001,$A21)&"") -> Dengeki PlayStation | C21: =IF($A21="","",INDEX(Apparitions!$B$1:$B$5001,$A21)&"") -> 38 | D21: =IF($A21="","",INDEX(Apparitions!$L$1:$L$5001,$A21)) -> 35440 | E21: =IF($A21="","",INDEX(Apparitions!$C$1:$C$5001,$A21)&"") -> 100 | F21: =IF($A21="","",INDEX(Apparitions!$H$1:$H$5001,$A21)&"") -> Biohazard 2 | G21: =IF($A21="","",INDEX(Apparitions!$I$1:$I$5001,$A21)&"") -> PlayStation | H21: =IF($A21="","",INDEX(Apparitions!$J$1:$J$5001,$A21)&"") -> Biohazard | I21: =IF($A21="","",INDEX(Apparitions!$G$1:$G$5001,$A21)&"") -> 3 | J21: =IF($A21="","",INDEX(Apparitions!$M$1:$M$5001,$A21)&"") -> Leon & Claire | K21: =IF($A21="","",INDEX(Apparitions!$K$1:$K$5001,$A21)) -> 2 | L21: =IF($A21="","",INDEX(Apparitions!$E$1:$E$5001,$A21)&"") -> × | M21: =IF($A21="","",INDEX(Apparitions!$F$1:$F$5001,$A21)&"") -> EXEMPLE - à supprimer | O21: =IF(I21="",0,IF(COUNTIF(I$16:I21,I21)=1,1,0)) -> 1 | P21: =IF(F21="",0,IF(COUNTIF(F$16:F21,F21)=1,1,0)) -> 1 | Q21: =IF(B21="","",B21&"|"&C21) -> Dengeki PlayStation|38 | R21: =IF(Q21="",0,IF(COUNTIF(Q$16:Q21,Q21)=1,1,0)) -> 0
A22: =IFERROR(MATCH(7,Apparitions!$N$1:$N$5001,0),"") -> 8 | B22: =IF($A22="","",INDEX(Apparitions!$A$1:$A$5001,$A22)&"") -> Sega Saturn Magazine | C22: =IF($A22="","",INDEX(Apparitions!$B$1:$B$5001,$A22)&"") -> 5 | D22: =IF($A22="","",INDEX(Apparitions!$L$1:$L$5001,$A22)) -> 35309 | E22: =IF($A22="","",INDEX(Apparitions!$C$1:$C$5001,$A22)&"") -> 1 | F22: =IF($A22="","",INDEX(Apparitions!$H$1:$H$5001,$A22)&"") -> Sakura Taisen | G22: =IF($A22="","",INDEX(Apparitions!$I$1:$I$5001,$A22)&"") -> Sega Saturn | H22: =IF($A22="","",INDEX(Apparitions!$J$1:$J$5001,$A22)&"") -> Sakura Taisen | I22: =IF($A22="","",INDEX(Apparitions!$G$1:$G$5001,$A22)&"") -> 4 | J22: =IF($A22="","",INDEX(Apparitions!$M$1:$M$5001,$A22)&"") -> Sakura au sabre | K22: =IF($A22="","",INDEX(Apparitions!$K$1:$K$5001,$A22)) -> 1 | L22: =IF($A22="","",INDEX(Apparitions!$E$1:$E$5001,$A22)&"") -> ○ | M22: =IF($A22="","",INDEX(Apparitions!$F$1:$F$5001,$A22)&"") -> EXEMPLE - à supprimer | O22: =IF(I22="",0,IF(COUNTIF(I$16:I22,I22)=1,1,0)) -> 0 | P22: =IF(F22="",0,IF(COUNTIF(F$16:F22,F22)=1,1,0)) -> 0 | Q22: =IF(B22="","",B22&"|"&C22) -> Sega Saturn Magazine|5 | R22: =IF(Q22="",0,IF(COUNTIF(Q$16:Q22,Q22)=1,1,0)) -> 1
A23: =IFERROR(MATCH(8,Apparitions!$N$1:$N$5001,0),"") -> 9 | B23: =IF($A23="","",INDEX(Apparitions!$A$1:$A$5001,$A23)&"") -> Weekly Famitsu | C23: =IF($A23="","",INDEX(Apparitions!$B$1:$B$5001,$A23)&"") -> 600 | D23: =IF($A23="","",INDEX(Apparitions!$L$1:$L$5001,$A23)) | E23: =IF($A23="","",INDEX(Apparitions!$C$1:$C$5001,$A23)&"") -> 4 | F23: =IF($A23="","",INDEX(Apparitions!$H$1:$H$5001,$A23)&"") -> Dragon Quest VII | G23: =IF($A23="","",INDEX(Apparitions!$I$1:$I$5001,$A23)&"") -> PlayStation | H23: =IF($A23="","",INDEX(Apparitions!$J$1:$J$5001,$A23)&"") -> Dragon Quest | I23: =IF($A23="","",INDEX(Apparitions!$G$1:$G$5001,$A23)&"") -> 5 | J23: =IF($A23="","",INDEX(Apparitions!$M$1:$M$5001,$A23)&"") -> Logo + illustration | K23: =IF($A23="","",INDEX(Apparitions!$K$1:$K$5001,$A23)) -> 2 | L23: =IF($A23="","",INDEX(Apparitions!$E$1:$E$5001,$A23)&"") -> × | M23: =IF($A23="","",INDEX(Apparitions!$F$1:$F$5001,$A23)&"") -> EXEMPLE - à supprimer | O23: =IF(I23="",0,IF(COUNTIF(I$16:I23,I23)=1,1,0)) -> 1 | P23: =IF(F23="",0,IF(COUNTIF(F$16:F23,F23)=1,1,0)) -> 1 | Q23: =IF(B23="","",B23&"|"&C23) -> Weekly Famitsu|600 | R23: =IF(Q23="",0,IF(COUNTIF(Q$16:Q23,Q23)=1,1,0)) -> 1
A24: =IFERROR(MATCH(9,Apparitions!$N$1:$N$5001,0),"") | B24: =IF($A24="","",INDEX(Apparitions!$A$1:$A$5001,$A24)&"") | C24: =IF($A24="","",INDEX(Apparitions!$B$1:$B$5001,$A24)&"") | D24: =IF($A24="","",INDEX(Apparitions!$L$1:$L$5001,$A24)) | E24: =IF($A24="","",INDEX(Apparitions!$C$1:$C$5001,$A24)&"") | F24: =IF($A24="","",INDEX(Apparitions!$H$1:$H$5001,$A24)&"") | G24: =IF($A24="","",INDEX(Apparitions!$I$1:$I$5001,$A24)&"") | H24: =IF($A24="","",INDEX(Apparitions!$J$1:$J$5001,$A24)&"") | I24: =IF($A24="","",INDEX(Apparitions!$G$1:$G$5001,$A24)&"") | J24: =IF($A24="","",INDEX(Apparitions!$M$1:$M$5001,$A24)&"") | K24: =IF($A24="","",INDEX(Apparitions!$K$1:$K$5001,$A24)) | L24: =IF($A24="","",INDEX(Apparitions!$E$1:$E$5001,$A24)&"") | M24: =IF($A24="","",INDEX(Apparitions!$F$1:$F$5001,$A24)&"") | O24: =IF(I24="",0,IF(COUNTIF(I$16:I24,I24)=1,1,0)) -> 0 | P24: =IF(F24="",0,IF(COUNTIF(F$16:F24,F24)=1,1,0)) -> 0 | Q24: =IF(B24="","",B24&"|"&C24) | R24: =IF(Q24="",0,IF(COUNTIF(Q$16:Q24,Q24)=1,1,0)) -> 0
A25: =IFERROR(MATCH(10,Apparitions!$N$1:$N$5001,0),"") | B25: =IF($A25="","",INDEX(Apparitions!$A$1:$A$5001,$A25)&"") | C25: =IF($A25="","",INDEX(Apparitions!$B$1:$B$5001,$A25)&"") | D25: =IF($A25="","",INDEX(Apparitions!$L$1:$L$5001,$A25)) | E25: =IF($A25="","",INDEX(Apparitions!$C$1:$C$5001,$A25)&"") | F25: =IF($A25="","",INDEX(Apparitions!$H$1:$H$5001,$A25)&"") | G25: =IF($A25="","",INDEX(Apparitions!$I$1:$I$5001,$A25)&"") | H25: =IF($A25="","",INDEX(Apparitions!$J$1:$J$5001,$A25)&"") | I25: =IF($A25="","",INDEX(Apparitions!$G$1:$G$5001,$A25)&"") | J25: =IF($A25="","",INDEX(Apparitions!$M$1:$M$5001,$A25)&"") | K25: =IF($A25="","",INDEX(Apparitions!$K$1:$K$5001,$A25)) | L25: =IF($A25="","",INDEX(Apparitions!$E$1:$E$5001,$A25)&"") | M25: =IF($A25="","",INDEX(Apparitions!$F$1:$F$5001,$A25)&"") | O25: =IF(I25="",0,IF(COUNTIF(I$16:I25,I25)=1,1,0)) -> 0 | P25: =IF(F25="",0,IF(COUNTIF(F$16:F25,F25)=1,1,0)) -> 0 | Q25: =IF(B25="","",B25&"|"&C25) | R25: =IF(Q25="",0,IF(COUNTIF(Q$16:Q25,Q25)=1,1,0)) -> 0
A26: =IFERROR(MATCH(11,Apparitions!$N$1:$N$5001,0),"") | B26: =IF($A26="","",INDEX(Apparitions!$A$1:$A$5001,$A26)&"") | C26: =IF($A26="","",INDEX(Apparitions!$B$1:$B$5001,$A26)&"") | D26: =IF($A26="","",INDEX(Apparitions!$L$1:$L$5001,$A26)) | E26: =IF($A26="","",INDEX(Apparitions!$C$1:$C$5001,$A26)&"") | F26: =IF($A26="","",INDEX(Apparitions!$H$1:$H$5001,$A26)&"") | G26: =IF($A26="","",INDEX(Apparitions!$I$1:$I$5001,$A26)&"") | H26: =IF($A26="","",INDEX(Apparitions!$J$1:$J$5001,$A26)&"") | I26: =IF($A26="","",INDEX(Apparitions!$G$1:$G$5001,$A26)&"") | J26: =IF($A26="","",INDEX(Apparitions!$M$1:$M$5001,$A26)&"") | K26: =IF($A26="","",INDEX(Apparitions!$K$1:$K$5001,$A26)) | L26: =IF($A26="","",INDEX(Apparitions!$E$1:$E$5001,$A26)&"") | M26: =IF($A26="","",INDEX(Apparitions!$F$1:$F$5001,$A26)&"") | O26: =IF(I26="",0,IF(COUNTIF(I$16:I26,I26)=1,1,0)) -> 0 | P26: =IF(F26="",0,IF(COUNTIF(F$16:F26,F26)=1,1,0)) -> 0 | Q26: =IF(B26="","",B26&"|"&C26) | R26: =IF(Q26="",0,IF(COUNTIF(Q$16:Q26,Q26)=1,1,0)) -> 0
A27: =IFERROR(MATCH(12,Apparitions!$N$1:$N$5001,0),"") | B27: =IF($A27="","",INDEX(Apparitions!$A$1:$A$5001,$A27)&"") | C27: =IF($A27="","",INDEX(Apparitions!$B$1:$B$5001,$A27)&"") | D27: =IF($A27="","",INDEX(Apparitions!$L$1:$L$5001,$A27)) | E27: =IF($A27="","",INDEX(Apparitions!$C$1:$C$5001,$A27)&"") | F27: =IF($A27="","",INDEX(Apparitions!$H$1:$H$5001,$A27)&"") | G27: =IF($A27="","",INDEX(Apparitions!$I$1:$I$5001,$A27)&"") | H27: =IF($A27="","",INDEX(Apparitions!$J$1:$J$5001,$A27)&"") | I27: =IF($A27="","",INDEX(Apparitions!$G$1:$G$5001,$A27)&"") | J27: =IF($A27="","",INDEX(Apparitions!$M$1:$M$5001,$A27)&"") | K27: =IF($A27="","",INDEX(Apparitions!$K$1:$K$5001,$A27)) | L27: =IF($A27="","",INDEX(Apparitions!$E$1:$E$5001,$A27)&"") | M27: =IF($A27="","",INDEX(Apparitions!$F$1:$F$5001,$A27)&"") | O27: =IF(I27="",0,IF(COUNTIF(I$16:I27,I27)=1,1,0)) -> 0 | P27: =IF(F27="",0,IF(COUNTIF(F$16:F27,F27)=1,1,0)) -> 0 | Q27: =IF(B27="","",B27&"|"&C27) | R27: =IF(Q27="",0,IF(COUNTIF(Q$16:Q27,Q27)=1,1,0)) -> 0
A28: =IFERROR(MATCH(13,Apparitions!$N$1:$N$5001,0),"") | B28: =IF($A28="","",INDEX(Apparitions!$A$1:$A$5001,$A28)&"") | C28: =IF($A28="","",INDEX(Apparitions!$B$1:$B$5001,$A28)&"") | D28: =IF($A28="","",INDEX(Apparitions!$L$1:$L$5001,$A28)) | E28: =IF($A28="","",INDEX(Apparitions!$C$1:$C$5001,$A28)&"") | F28: =IF($A28="","",INDEX(Apparitions!$H$1:$H$5001,$A28)&"") | G28: =IF($A28="","",INDEX(Apparitions!$I$1:$I$5001,$A28)&"") | H28: =IF($A28="","",INDEX(Apparitions!$J$1:$J$5001,$A28)&"") | I28: =IF($A28="","",INDEX(Apparitions!$G$1:$G$5001,$A28)&"") | J28: =IF($A28="","",INDEX(Apparitions!$M$1:$M$5001,$A28)&"") | K28: =IF($A28="","",INDEX(Apparitions!$K$1:$K$5001,$A28)) | L28: =IF($A28="","",INDEX(Apparitions!$E$1:$E$5001,$A28)&"") | M28: =IF($A28="","",INDEX(Apparitions!$F$1:$F$5001,$A28)&"") | O28: =IF(I28="",0,IF(COUNTIF(I$16:I28,I28)=1,1,0)) -> 0 | P28: =IF(F28="",0,IF(COUNTIF(F$16:F28,F28)=1,1,0)) -> 0 | Q28: =IF(B28="","",B28&"|"&C28) | R28: =IF(Q28="",0,IF(COUNTIF(Q$16:Q28,Q28)=1,1,0)) -> 0
A29: =IFERROR(MATCH(14,Apparitions!$N$1:$N$5001,0),"") | B29: =IF($A29="","",INDEX(Apparitions!$A$1:$A$5001,$A29)&"") | C29: =IF($A29="","",INDEX(Apparitions!$B$1:$B$5001,$A29)&"") | D29: =IF($A29="","",INDEX(Apparitions!$L$1:$L$5001,$A29)) | E29: =IF($A29="","",INDEX(Apparitions!$C$1:$C$5001,$A29)&"") | F29: =IF($A29="","",INDEX(Apparitions!$H$1:$H$5001,$A29)&"") | G29: =IF($A29="","",INDEX(Apparitions!$I$1:$I$5001,$A29)&"") | H29: =IF($A29="","",INDEX(Apparitions!$J$1:$J$5001,$A29)&"") | I29: =IF($A29="","",INDEX(Apparitions!$G$1:$G$5001,$A29)&"") | J29: =IF($A29="","",INDEX(Apparitions!$M$1:$M$5001,$A29)&"") | K29: =IF($A29="","",INDEX(Apparitions!$K$1:$K$5001,$A29)) | L29: =IF($A29="","",INDEX(Apparitions!$E$1:$E$5001,$A29)&"") | M29: =IF($A29="","",INDEX(Apparitions!$F$1:$F$5001,$A29)&"") | O29: =IF(I29="",0,IF(COUNTIF(I$16:I29,I29)=1,1,0)) -> 0 | P29: =IF(F29="",0,IF(COUNTIF(F$16:F29,F29)=1,1,0)) -> 0 | Q29: =IF(B29="","",B29&"|"&C29) | R29: =IF(Q29="",0,IF(COUNTIF(Q$16:Q29,Q29)=1,1,0)) -> 0
A30: =IFERROR(MATCH(15,Apparitions!$N$1:$N$5001,0),"") | B30: =IF($A30="","",INDEX(Apparitions!$A$1:$A$5001,$A30)&"") | C30: =IF($A30="","",INDEX(Apparitions!$B$1:$B$5001,$A30)&"") | D30: =IF($A30="","",INDEX(Apparitions!$L$1:$L$5001,$A30)) | E30: =IF($A30="","",INDEX(Apparitions!$C$1:$C$5001,$A30)&"") | F30: =IF($A30="","",INDEX(Apparitions!$H$1:$H$5001,$A30)&"") | G30: =IF($A30="","",INDEX(Apparitions!$I$1:$I$5001,$A30)&"") | H30: =IF($A30="","",INDEX(Apparitions!$J$1:$J$5001,$A30)&"") | I30: =IF($A30="","",INDEX(Apparitions!$G$1:$G$5001,$A30)&"") | J30: =IF($A30="","",INDEX(Apparitions!$M$1:$M$5001,$A30)&"") | K30: =IF($A30="","",INDEX(Apparitions!$K$1:$K$5001,$A30)) | L30: =IF($A30="","",INDEX(Apparitions!$E$1:$E$5001,$A30)&"") | M30: =IF($A30="","",INDEX(Apparitions!$F$1:$F$5001,$A30)&"") | O30: =IF(I30="",0,IF(COUNTIF(I$16:I30,I30)=1,1,0)) -> 0 | P30: =IF(F30="",0,IF(COUNTIF(F$16:F30,F30)=1,1,0)) -> 0 | Q30: =IF(B30="","",B30&"|"&C30) | R30: =IF(Q30="",0,IF(COUNTIF(Q$16:Q30,Q30)=1,1,0)) -> 0
A31: =IFERROR(MATCH(16,Apparitions!$N$1:$N$5001,0),"") | B31: =IF($A31="","",INDEX(Apparitions!$A$1:$A$5001,$A31)&"") | C31: =IF($A31="","",INDEX(Apparitions!$B$1:$B$5001,$A31)&"") | D31: =IF($A31="","",INDEX(Apparitions!$L$1:$L$5001,$A31)) | E31: =IF($A31="","",INDEX(Apparitions!$C$1:$C$5001,$A31)&"") | F31: =IF($A31="","",INDEX(Apparitions!$H$1:$H$5001,$A31)&"") | G31: =IF($A31="","",INDEX(Apparitions!$I$1:$I$5001,$A31)&"") | H31: =IF($A31="","",INDEX(Apparitions!$J$1:$J$5001,$A31)&"") | I31: =IF($A31="","",INDEX(Apparitions!$G$1:$G$5001,$A31)&"") | J31: =IF($A31="","",INDEX(Apparitions!$M$1:$M$5001,$A31)&"") | K31: =IF($A31="","",INDEX(Apparitions!$K$1:$K$5001,$A31)) | L31: =IF($A31="","",INDEX(Apparitions!$E$1:$E$5001,$A31)&"") | M31: =IF($A31="","",INDEX(Apparitions!$F$1:$F$5001,$A31)&"") | O31: =IF(I31="",0,IF(COUNTIF(I$16:I31,I31)=1,1,0)) -> 0 | P31: =IF(F31="",0,IF(COUNTIF(F$16:F31,F31)=1,1,0)) -> 0 | Q31: =IF(B31="","",B31&"|"&C31) | R31: =IF(Q31="",0,IF(COUNTIF(Q$16:Q31,Q31)=1,1,0)) -> 0
A32: =IFERROR(MATCH(17,Apparitions!$N$1:$N$5001,0),"") | B32: =IF($A32="","",INDEX(Apparitions!$A$1:$A$5001,$A32)&"") | C32: =IF($A32="","",INDEX(Apparitions!$B$1:$B$5001,$A32)&"") | D32: =IF($A32="","",INDEX(Apparitions!$L$1:$L$5001,$A32)) | E32: =IF($A32="","",INDEX(Apparitions!$C$1:$C$5001,$A32)&"") | F32: =IF($A32="","",INDEX(Apparitions!$H$1:$H$5001,$A32)&"") | G32: =IF($A32="","",INDEX(Apparitions!$I$1:$I$5001,$A32)&"") | H32: =IF($A32="","",INDEX(Apparitions!$J$1:$J$5001,$A32)&"") | I32: =IF($A32="","",INDEX(Apparitions!$G$1:$G$5001,$A32)&"") | J32: =IF($A32="","",INDEX(Apparitions!$M$1:$M$5001,$A32)&"") | K32: =IF($A32="","",INDEX(Apparitions!$K$1:$K$5001,$A32)) | L32: =IF($A32="","",INDEX(Apparitions!$E$1:$E$5001,$A32)&"") | M32: =IF($A32="","",INDEX(Apparitions!$F$1:$F$5001,$A32)&"") | O32: =IF(I32="",0,IF(COUNTIF(I$16:I32,I32)=1,1,0)) -> 0 | P32: =IF(F32="",0,IF(COUNTIF(F$16:F32,F32)=1,1,0)) -> 0 | Q32: =IF(B32="","",B32&"|"&C32) | R32: =IF(Q32="",0,IF(COUNTIF(Q$16:Q32,Q32)=1,1,0)) -> 0
A33: =IFERROR(MATCH(18,Apparitions!$N$1:$N$5001,0),"") | B33: =IF($A33="","",INDEX(Apparitions!$A$1:$A$5001,$A33)&"") | C33: =IF($A33="","",INDEX(Apparitions!$B$1:$B$5001,$A33)&"") | D33: =IF($A33="","",INDEX(Apparitions!$L$1:$L$5001,$A33)) | E33: =IF($A33="","",INDEX(Apparitions!$C$1:$C$5001,$A33)&"") | F33: =IF($A33="","",INDEX(Apparitions!$H$1:$H$5001,$A33)&"") | G33: =IF($A33="","",INDEX(Apparitions!$I$1:$I$5001,$A33)&"") | H33: =IF($A33="","",INDEX(Apparitions!$J$1:$J$5001,$A33)&"") | I33: =IF($A33="","",INDEX(Apparitions!$G$1:$G$5001,$A33)&"") | J33: =IF($A33="","",INDEX(Apparitions!$M$1:$M$5001,$A33)&"") | K33: =IF($A33="","",INDEX(Apparitions!$K$1:$K$5001,$A33)) | L33: =IF($A33="","",INDEX(Apparitions!$E$1:$E$5001,$A33)&"") | M33: =IF($A33="","",INDEX(Apparitions!$F$1:$F$5001,$A33)&"") | O33: =IF(I33="",0,IF(COUNTIF(I$16:I33,I33)=1,1,0)) -> 0 | P33: =IF(F33="",0,IF(COUNTIF(F$16:F33,F33)=1,1,0)) -> 0 | Q33: =IF(B33="","",B33&"|"&C33) | R33: =IF(Q33="",0,IF(COUNTIF(Q$16:Q33,Q33)=1,1,0)) -> 0
A34: =IFERROR(MATCH(19,Apparitions!$N$1:$N$5001,0),"") | B34: =IF($A34="","",INDEX(Apparitions!$A$1:$A$5001,$A34)&"") | C34: =IF($A34="","",INDEX(Apparitions!$B$1:$B$5001,$A34)&"") | D34: =IF($A34="","",INDEX(Apparitions!$L$1:$L$5001,$A34)) | E34: =IF($A34="","",INDEX(Apparitions!$C$1:$C$5001,$A34)&"") | F34: =IF($A34="","",INDEX(Apparitions!$H$1:$H$5001,$A34)&"") | G34: =IF($A34="","",INDEX(Apparitions!$I$1:$I$5001,$A34)&"") | H34: =IF($A34="","",INDEX(Apparitions!$J$1:$J$5001,$A34)&"") | I34: =IF($A34="","",INDEX(Apparitions!$G$1:$G$5001,$A34)&"") | J34: =IF($A34="","",INDEX(Apparitions!$M$1:$M$5001,$A34)&"") | K34: =IF($A34="","",INDEX(Apparitions!$K$1:$K$5001,$A34)) | L34: =IF($A34="","",INDEX(Apparitions!$E$1:$E$5001,$A34)&"") | M34: =IF($A34="","",INDEX(Apparitions!$F$1:$F$5001,$A34)&"") | O34: =IF(I34="",0,IF(COUNTIF(I$16:I34,I34)=1,1,0)) -> 0 | P34: =IF(F34="",0,IF(COUNTIF(F$16:F34,F34)=1,1,0)) -> 0 | Q34: =IF(B34="","",B34&"|"&C34) | R34: =IF(Q34="",0,IF(COUNTIF(Q$16:Q34,Q34)=1,1,0)) -> 0
A35: =IFERROR(MATCH(20,Apparitions!$N$1:$N$5001,0),"") | B35: =IF($A35="","",INDEX(Apparitions!$A$1:$A$5001,$A35)&"") | C35: =IF($A35="","",INDEX(Apparitions!$B$1:$B$5001,$A35)&"") | D35: =IF($A35="","",INDEX(Apparitions!$L$1:$L$5001,$A35)) | E35: =IF($A35="","",INDEX(Apparitions!$C$1:$C$5001,$A35)&"") | F35: =IF($A35="","",INDEX(Apparitions!$H$1:$H$5001,$A35)&"") | G35: =IF($A35="","",INDEX(Apparitions!$I$1:$I$5001,$A35)&"") | H35: =IF($A35="","",INDEX(Apparitions!$J$1:$J$5001,$A35)&"") | I35: =IF($A35="","",INDEX(Apparitions!$G$1:$G$5001,$A35)&"") | J35: =IF($A35="","",INDEX(Apparitions!$M$1:$M$5001,$A35)&"") | K35: =IF($A35="","",INDEX(Apparitions!$K$1:$K$5001,$A35)) | L35: =IF($A35="","",INDEX(Apparitions!$E$1:$E$5001,$A35)&"") | M35: =IF($A35="","",INDEX(Apparitions!$F$1:$F$5001,$A35)&"") | O35: =IF(I35="",0,IF(COUNTIF(I$16:I35,I35)=1,1,0)) -> 0 | P35: =IF(F35="",0,IF(COUNTIF(F$16:F35,F35)=1,1,0)) -> 0 | Q35: =IF(B35="","",B35&"|"&C35) | R35: =IF(Q35="",0,IF(COUNTIF(Q$16:Q35,Q35)=1,1,0)) -> 0
A36: =IFERROR(MATCH(21,Apparitions!$N$1:$N$5001,0),"") | B36: =IF($A36="","",INDEX(Apparitions!$A$1:$A$5001,$A36)&"") | C36: =IF($A36="","",INDEX(Apparitions!$B$1:$B$5001,$A36)&"") | D36: =IF($A36="","",INDEX(Apparitions!$L$1:$L$5001,$A36)) | E36: =IF($A36="","",INDEX(Apparitions!$C$1:$C$5001,$A36)&"") | F36: =IF($A36="","",INDEX(Apparitions!$H$1:$H$5001,$A36)&"") | G36: =IF($A36="","",INDEX(Apparitions!$I$1:$I$5001,$A36)&"") | H36: =IF($A36="","",INDEX(Apparitions!$J$1:$J$5001,$A36)&"") | I36: =IF($A36="","",INDEX(Apparitions!$G$1:$G$5001,$A36)&"") | J36: =IF($A36="","",INDEX(Apparitions!$M$1:$M$5001,$A36)&"") | K36: =IF($A36="","",INDEX(Apparitions!$K$1:$K$5001,$A36)) | L36: =IF($A36="","",INDEX(Apparitions!$E$1:$E$5001,$A36)&"") | M36: =IF($A36="","",INDEX(Apparitions!$F$1:$F$5001,$A36)&"") | O36: =IF(I36="",0,IF(COUNTIF(I$16:I36,I36)=1,1,0)) -> 0 | P36: =IF(F36="",0,IF(COUNTIF(F$16:F36,F36)=1,1,0)) -> 0 | Q36: =IF(B36="","",B36&"|"&C36) | R36: =IF(Q36="",0,IF(COUNTIF(Q$16:Q36,Q36)=1,1,0)) -> 0
A37: =IFERROR(MATCH(22,Apparitions!$N$1:$N$5001,0),"") | B37: =IF($A37="","",INDEX(Apparitions!$A$1:$A$5001,$A37)&"") | C37: =IF($A37="","",INDEX(Apparitions!$B$1:$B$5001,$A37)&"") | D37: =IF($A37="","",INDEX(Apparitions!$L$1:$L$5001,$A37)) | E37: =IF($A37="","",INDEX(Apparitions!$C$1:$C$5001,$A37)&"") | F37: =IF($A37="","",INDEX(Apparitions!$H$1:$H$5001,$A37)&"") | G37: =IF($A37="","",INDEX(Apparitions!$I$1:$I$5001,$A37)&"") | H37: =IF($A37="","",INDEX(Apparitions!$J$1:$J$5001,$A37)&"") | I37: =IF($A37="","",INDEX(Apparitions!$G$1:$G$5001,$A37)&"") | J37: =IF($A37="","",INDEX(Apparitions!$M$1:$M$5001,$A37)&"") | K37: =IF($A37="","",INDEX(Apparitions!$K$1:$K$5001,$A37)) | L37: =IF($A37="","",INDEX(Apparitions!$E$1:$E$5001,$A37)&"") | M37: =IF($A37="","",INDEX(Apparitions!$F$1:$F$5001,$A37)&"") | O37: =IF(I37="",0,IF(COUNTIF(I$16:I37,I37)=1,1,0)) -> 0 | P37: =IF(F37="",0,IF(COUNTIF(F$16:F37,F37)=1,1,0)) -> 0 | Q37: =IF(B37="","",B37&"|"&C37) | R37: =IF(Q37="",0,IF(COUNTIF(Q$16:Q37,Q37)=1,1,0)) -> 0
A38: =IFERROR(MATCH(23,Apparitions!$N$1:$N$5001,0),"") | B38: =IF($A38="","",INDEX(Apparitions!$A$1:$A$5001,$A38)&"") | C38: =IF($A38="","",INDEX(Apparitions!$B$1:$B$5001,$A38)&"") | D38: =IF($A38="","",INDEX(Apparitions!$L$1:$L$5001,$A38)) | E38: =IF($A38="","",INDEX(Apparitions!$C$1:$C$5001,$A38)&"") | F38: =IF($A38="","",INDEX(Apparitions!$H$1:$H$5001,$A38)&"") | G38: =IF($A38="","",INDEX(Apparitions!$I$1:$I$5001,$A38)&"") | H38: =IF($A38="","",INDEX(Apparitions!$J$1:$J$5001,$A38)&"") | I38: =IF($A38="","",INDEX(Apparitions!$G$1:$G$5001,$A38)&"") | J38: =IF($A38="","",INDEX(Apparitions!$M$1:$M$5001,$A38)&"") | K38: =IF($A38="","",INDEX(Apparitions!$K$1:$K$5001,$A38)) | L38: =IF($A38="","",INDEX(Apparitions!$E$1:$E$5001,$A38)&"") | M38: =IF($A38="","",INDEX(Apparitions!$F$1:$F$5001,$A38)&"") | O38: =IF(I38="",0,IF(COUNTIF(I$16:I38,I38)=1,1,0)) -> 0 | P38: =IF(F38="",0,IF(COUNTIF(F$16:F38,F38)=1,1,0)) -> 0 | Q38: =IF(B38="","",B38&"|"&C38) | R38: =IF(Q38="",0,IF(COUNTIF(Q$16:Q38,Q38)=1,1,0)) -> 0
A39: =IFERROR(MATCH(24,Apparitions!$N$1:$N$5001,0),"") | B39: =IF($A39="","",INDEX(Apparitions!$A$1:$A$5001,$A39)&"") | C39: =IF($A39="","",INDEX(Apparitions!$B$1:$B$5001,$A39)&"") | D39: =IF($A39="","",INDEX(Apparitions!$L$1:$L$5001,$A39)) | E39: =IF($A39="","",INDEX(Apparitions!$C$1:$C$5001,$A39)&"") | F39: =IF($A39="","",INDEX(Apparitions!$H$1:$H$5001,$A39)&"") | G39: =IF($A39="","",INDEX(Apparitions!$I$1:$I$5001,$A39)&"") | H39: =IF($A39="","",INDEX(Apparitions!$J$1:$J$5001,$A39)&"") | I39: =IF($A39="","",INDEX(Apparitions!$G$1:$G$5001,$A39)&"") | J39: =IF($A39="","",INDEX(Apparitions!$M$1:$M$5001,$A39)&"") | K39: =IF($A39="","",INDEX(Apparitions!$K$1:$K$5001,$A39)) | L39: =IF($A39="","",INDEX(Apparitions!$E$1:$E$5001,$A39)&"") | M39: =IF($A39="","",INDEX(Apparitions!$F$1:$F$5001,$A39)&"") | O39: =IF(I39="",0,IF(COUNTIF(I$16:I39,I39)=1,1,0)) -> 0 | P39: =IF(F39="",0,IF(COUNTIF(F$16:F39,F39)=1,1,0)) -> 0 | Q39: =IF(B39="","",B39&"|"&C39) | R39: =IF(Q39="",0,IF(COUNTIF(Q$16:Q39,Q39)=1,1,0)) -> 0
A40: =IFERROR(MATCH(25,Apparitions!$N$1:$N$5001,0),"") | B40: =IF($A40="","",INDEX(Apparitions!$A$1:$A$5001,$A40)&"") | C40: =IF($A40="","",INDEX(Apparitions!$B$1:$B$5001,$A40)&"") | D40: =IF($A40="","",INDEX(Apparitions!$L$1:$L$5001,$A40)) | E40: =IF($A40="","",INDEX(Apparitions!$C$1:$C$5001,$A40)&"") | F40: =IF($A40="","",INDEX(Apparitions!$H$1:$H$5001,$A40)&"") | G40: =IF($A40="","",INDEX(Apparitions!$I$1:$I$5001,$A40)&"") | H40: =IF($A40="","",INDEX(Apparitions!$J$1:$J$5001,$A40)&"") | I40: =IF($A40="","",INDEX(Apparitions!$G$1:$G$5001,$A40)&"") | J40: =IF($A40="","",INDEX(Apparitions!$M$1:$M$5001,$A40)&"") | K40: =IF($A40="","",INDEX(Apparitions!$K$1:$K$5001,$A40)) | L40: =IF($A40="","",INDEX(Apparitions!$E$1:$E$5001,$A40)&"") | M40: =IF($A40="","",INDEX(Apparitions!$F$1:$F$5001,$A40)&"") | O40: =IF(I40="",0,IF(COUNTIF(I$16:I40,I40)=1,1,0)) -> 0 | P40: =IF(F40="",0,IF(COUNTIF(F$16:F40,F40)=1,1,0)) -> 0 | Q40: =IF(B40="","",B40&"|"&C40) | R40: =IF(Q40="",0,IF(COUNTIF(Q$16:Q40,Q40)=1,1,0)) -> 0
A41: =IFERROR(MATCH(26,Apparitions!$N$1:$N$5001,0),"") | B41: =IF($A41="","",INDEX(Apparitions!$A$1:$A$5001,$A41)&"") | C41: =IF($A41="","",INDEX(Apparitions!$B$1:$B$5001,$A41)&"") | D41: =IF($A41="","",INDEX(Apparitions!$L$1:$L$5001,$A41)) | E41: =IF($A41="","",INDEX(Apparitions!$C$1:$C$5001,$A41)&"") | F41: =IF($A41="","",INDEX(Apparitions!$H$1:$H$5001,$A41)&"") | G41: =IF($A41="","",INDEX(Apparitions!$I$1:$I$5001,$A41)&"") | H41: =IF($A41="","",INDEX(Apparitions!$J$1:$J$5001,$A41)&"") | I41: =IF($A41="","",INDEX(Apparitions!$G$1:$G$5001,$A41)&"") | J41: =IF($A41="","",INDEX(Apparitions!$M$1:$M$5001,$A41)&"") | K41: =IF($A41="","",INDEX(Apparitions!$K$1:$K$5001,$A41)) | L41: =IF($A41="","",INDEX(Apparitions!$E$1:$E$5001,$A41)&"") | M41: =IF($A41="","",INDEX(Apparitions!$F$1:$F$5001,$A41)&"") | O41: =IF(I41="",0,IF(COUNTIF(I$16:I41,I41)=1,1,0)) -> 0 | P41: =IF(F41="",0,IF(COUNTIF(F$16:F41,F41)=1,1,0)) -> 0 | Q41: =IF(B41="","",B41&"|"&C41) | R41: =IF(Q41="",0,IF(COUNTIF(Q$16:Q41,Q41)=1,1,0)) -> 0
...

Sheet Apparitions
A1: Magazine | B1: Numéro | C1: Page | D1: Pub | E1: En vente ○ / × | F1: Remarques | G1: ID pub | H1: Jeu | I1: Plateforme | J1: Série | K1: Nb pages | L1: Date parution | M1: Description pub | N1: (technique)
A2: Weekly Famitsu | B2: 421 | C2: 12 | D2: 1 | Final Fantasy VII (PlayStation) - Cloud devant Midgar | E2: ○ | F2: EXEMPLE - à supprimer | G2: =IF(D2="","",IFERROR(VALUE(LEFT(D2,FIND(" |",D2&" |")-1)),"?")) -> 1 | H2: =IF(G2="","",IF(G2="?","⚠ pub inconnue",IFERROR(INDEX(Pubs!$B$2:$B$3001,MATCH(G2,Pubs!$A$2:$A$3001,0))&"","⚠ pub inconnue"))) -> Final Fantasy VII | I2: =IF(OR(G2="",G2="?"),"",IFERROR(INDEX(Pubs!$C$2:$C$3001,MATCH(G2,Pubs!$A$2:$A$3001,0))&"","")) -> PlayStation | J2: =IF(OR(G2="",G2="?"),"",IFERROR(INDEX(Pubs!$G$2:$G$3001,MATCH(G2,Pubs!$A$2:$A$3001,0))&"","")) -> Final Fantasy | K2: =IF(OR(G2="",G2="?"),"",IFERROR(INDEX(Pubs!$E$2:$E$3001,MATCH(G2,Pubs!$A$2:$A$3001,0)),"")) -> 2 | L2: =IF(A2="","",IFERROR(1/(1/INDEX(Numéros!$C$2:$C$3001,MATCH(A2&"|"&B2,Numéros!$F$2:$F$3001,0))),"")) -> 35433 | M2: =IF(OR(G2="",G2="?"),"",IFERROR(INDEX(Pubs!$D$2:$D$3001,MATCH(G2,Pubs!$A$2:$A$3001,0))&"","")) -> Cloud devant Midgar | N2: =N(N1)+IF(AND(A2<>"",OR(Recherche!$C$4="",A2=Recherche!$C$4),OR(Recherche!$C$5="",B2&""=Recherche!$C$5&""),OR(Recherche!$C$6="",IFERROR(YEAR(L2),0)=Recherche!$C$6),OR(Recherche!$C$7="",ISNUMBER(SEARCH(Recherche!$C$7,H2))),OR(Recherche!$C$8="",J2=Recherche!$C$8),OR(Recherche!$C$9="",I2=Recherche!$C$9),OR(Recherche!$C$10="",G2&""=Recherche!$C$10&""),OR(Recherche!$C$11="",E2=Recherche!$C$11),OR(Recherche!$C$12="",ISNUMBER(SEARCH(Recherche!$C$12,M2&" "&F2)))),1,0) -> 1
A3: Weekly Famitsu | B3: 421 | C3: 40 | D3: 4 | Sakura Taisen (Sega Saturn) - Sakura au sabre | E3: × | F3: EXEMPLE - à supprimer | G3: =IF(D3="","",IFERROR(VALUE(LEFT(D3,FIND(" |",D3&" |")-1)),"?")) -> 4 | H3: =IF(G3="","",IF(G3="?","⚠ pub inconnue",IFERROR(INDEX(Pubs!$B$2:$B$3001,MATCH(G3,Pubs!$A$2:$A$3001,0))&"","⚠ pub inconnue"))) -> Sakura Taisen | I3: =IF(OR(G3="",G3="?"),"",IFERROR(INDEX(Pubs!$C$2:$C$3001,MATCH(G3,Pubs!$A$2:$A$3001,0))&"","")) -> Sega Saturn | J3: =IF(OR(G3="",G3="?"),"",IFERROR(INDEX(Pubs!$G$2:$G$3001,MATCH(G3,Pubs!$A$2:$A$3001,0))&"","")) -> Sakura Taisen | K3: =IF(OR(G3="",G3="?"),"",IFERROR(INDEX(Pubs!$E$2:$E$3001,MATCH(G3,Pubs!$A$2:$A$3001,0)),"")) -> 1 | L3: =IF(A3="","",IFERROR(1/(1/INDEX(Numéros!$C$2:$C$3001,MATCH(A3&"|"&B3,Numéros!$F$2:$F$3001,0))),"")) -> 35433 | M3: =IF(OR(G3="",G3="?"),"",IFERROR(INDEX(Pubs!$D$2:$D$3001,MATCH(G3,Pubs!$A$2:$A$3001,0))&"","")) -> Sakura au sabre | N3: =N(N2)+IF(AND(A3<>"",OR(Recherche!$C$4="",A3=Recherche!$C$4),OR(Recherche!$C$5="",B3&""=Recherche!$C$5&""),OR(Recherche!$C$6="",IFERROR(YEAR(L3),0)=Recherche!$C$6),OR(Recherche!$C$7="",ISNUMBER(SEARCH(Recherche!$C$7,H3))),OR(Recherche!$C$8="",J3=Recherche!$C$8),OR(Recherche!$C$9="",I3=Recherche!$C$9),OR(Recherche!$C$10="",G3&""=Recherche!$C$10&""),OR(Recherche!$C$11="",E3=Recherche!$C$11),OR(Recherche!$C$12="",ISNUMBER(SEARCH(Recherche!$C$12,M3&" "&F3)))),1,0) -> 2
A4: Weekly Famitsu | B4: 425 | C4: 8 | D4: 1 | Final Fantasy VII (PlayStation) - Cloud devant Midgar | E4: × | F4: EXEMPLE - à supprimer | G4: =IF(D4="","",IFERROR(VALUE(LEFT(D4,FIND(" |",D4&" |")-1)),"?")) -> 1 | H4: =IF(G4="","",IF(G4="?","⚠ pub inconnue",IFERROR(INDEX(Pubs!$B$2:$B$3001,MATCH(G4,Pubs!$A$2:$A$3001,0))&"","⚠ pub inconnue"))) -> Final Fantasy VII | I4: =IF(OR(G4="",G4="?"),"",IFERROR(INDEX(Pubs!$C$2:$C$3001,MATCH(G4,Pubs!$A$2:$A$3001,0))&"","")) -> PlayStation | J4: =IF(OR(G4="",G4="?"),"",IFERROR(INDEX(Pubs!$G$2:$G$3001,MATCH(G4,Pubs!$A$2:$A$3001,0))&"","")) -> Final Fantasy | K4: =IF(OR(G4="",G4="?"),"",IFERROR(INDEX(Pubs!$E$2:$E$3001,MATCH(G4,Pubs!$A$2:$A$3001,0)),"")) -> 2 | L4: =IF(A4="","",IFERROR(1/(1/INDEX(Numéros!$C$2:$C$3001,MATCH(A4&"|"&B4,Numéros!$F$2:$F$3001,0))),"")) -> 35461 | M4: =IF(OR(G4="",G4="?"),"",IFERROR(INDEX(Pubs!$D$2:$D$3001,MATCH(G4,Pubs!$A$2:$A$3001,0))&"","")) -> Cloud devant Midgar | N4: =N(N3)+IF(AND(A4<>"",OR(Recherche!$C$4="",A4=Recherche!$C$4),OR(Recherche!$C$5="",B4&""=Recherche!$C$5&""),OR(Recherche!$C$6="",IFERROR(YEAR(L4),0)=Recherche!$C$6),OR(Recherche!$C$7="",ISNUMBER(SEARCH(Recherche!$C$7,H4))),OR(Recherche!$C$8="",J4=Recherche!$C$8),OR(Recherche!$C$9="",I4=Recherche!$C$9),OR(Recherche!$C$10="",G4&""=Recherche!$C$10&""),OR(Recherche!$C$11="",E4=Recherche!$C$11),OR(Recherche!$C$12="",ISNUMBER(SEARCH(Recherche!$C$12,M4&" "&F4)))),1,0) -> 3
A5: Weekly Famitsu | B5: 430 | C5: 2 | D5: 2 | Final Fantasy VII (PlayStation) - Aerith, fond fleurs | E5: ○ | F5: EXEMPLE - à supprimer | G5: =IF(D5="","",IFERROR(VALUE(LEFT(D5,FIND(" |",D5&" |")-1)),"?")) -> 2 | H5: =IF(G5="","",IF(G5="?","⚠ pub inconnue",IFERROR(INDEX(Pubs!$B$2:$B$3001,MATCH(G5,Pubs!$A$2:$A$3001,0))&"","⚠ pub inconnue"))) -> Final Fantasy VII | I5: =IF(OR(G5="",G5="?"),"",IFERROR(INDEX(Pubs!$C$2:$C$3001,MATCH(G5,Pubs!$A$2:$A$3001,0))&"","")) -> PlayStation | J5: =IF(OR(G5="",G5="?"),"",IFERROR(INDEX(Pubs!$G$2:$G$3001,MATCH(G5,Pubs!$A$2:$A$3001,0))&"","")) -> Final Fantasy | K5: =IF(OR(G5="",G5="?"),"",IFERROR(INDEX(Pubs!$E$2:$E$3001,MATCH(G5,Pubs!$A$2:$A$3001,0)),"")) -> 1 | L5: =IF(A5="","",IFERROR(1/(1/INDEX(Numéros!$C$2:$C$3001,MATCH(A5&"|"&B5,Numéros!$F$2:$F$3001,0))),"")) -> 35496 | M5: =IF(OR(G5="",G5="?"),"",IFERROR(INDEX(Pubs!$D$2:$D$3001,MATCH(G5,Pubs!$A$2:$A$3001,0))&"","")) -> Aerith, fond fleurs | N5: =N(N4)+IF(AND(A5<>"",OR(Recherche!$C$4="",A5=Recherche!$C$4),OR(Recherche!$C$5="",B5&""=Recherche!$C$5&""),OR(Recherche!$C$6="",IFERROR(YEAR(L5),0)=Recherche!$C$6),OR(Recherche!$C$7="",ISNUMBER(SEARCH(Recherche!$C$7,H5))),OR(Recherche!$C$8="",J5=Recherche!$C$8),OR(Recherche!$C$9="",I5=Recherche!$C$9),OR(Recherche!$C$10="",G5&""=Recherche!$C$10&""),OR(Recherche!$C$11="",E5=Recherche!$C$11),OR(Recherche!$C$12="",ISNUMBER(SEARCH(Recherche!$C$12,M5&" "&F5)))),1,0) -> 4
A6: Dengeki PlayStation | B6: 38 | C6: 2 | D6: 1 | Final Fantasy VII (PlayStation) - Cloud devant Midgar | E6: ○ | F6: EXEMPLE - à supprimer | G6: =IF(D6="","",IFERROR(VALUE(LEFT(D6,FIND(" |",D6&" |")-1)),"?")) -> 1 | H6: =IF(G6="","",IF(G6="?","⚠ pub inconnue",IFERROR(INDEX(Pubs!$B$2:$B$3001,MATCH(G6,Pubs!$A$2:$A$3001,0))&"","⚠ pub inconnue"))) -> Final Fantasy VII | I6: =IF(OR(G6="",G6="?"),"",IFERROR(INDEX(Pubs!$C$2:$C$3001,MATCH(G6,Pubs!$A$2:$A$3001,0))&"","")) -> PlayStation | J6: =IF(OR(G6="",G6="?"),"",IFERROR(INDEX(Pubs!$G$2:$G$3001,MATCH(G6,Pubs!$A$2:$A$3001,0))&"","")) -> Final Fantasy | K6: =IF(OR(G6="",G6="?"),"",IFERROR(INDEX(Pubs!$E$2:$E$3001,MATCH(G6,Pubs!$A$2:$A$3001,0)),"")) -> 2 | L6: =IF(A6="","",IFERROR(1/(1/INDEX(Numéros!$C$2:$C$3001,MATCH(A6&"|"&B6,Numéros!$F$2:$F$3001,0))),"")) -> 35440 | M6: =IF(OR(G6="",G6="?"),"",IFERROR(INDEX(Pubs!$D$2:$D$3001,MATCH(G6,Pubs!$A$2:$A$3001,0))&"","")) -> Cloud devant Midgar | N6: =N(N5)+IF(AND(A6<>"",OR(Recherche!$C$4="",A6=Recherche!$C$4),OR(Recherche!$C$5="",B6&""=Recherche!$C$5&""),OR(Recherche!$C$6="",IFERROR(YEAR(L6),0)=Recherche!$C$6),OR(Recherche!$C$7="",ISNUMBER(SEARCH(Recherche!$C$7,H6))),OR(Recherche!$C$8="",J6=Recherche!$C$8),OR(Recherche!$C$9="",I6=Recherche!$C$9),OR(Recherche!$C$10="",G6&""=Recherche!$C$10&""),OR(Recherche!$C$11="",E6=Recherche!$C$11),OR(Recherche!$C$12="",ISNUMBER(SEARCH(Recherche!$C$12,M6&" "&F6)))),1,0) -> 5
A7: Dengeki PlayStation | B7: 38 | C7: 100 | D7: 3 | Biohazard 2 (PlayStation) - Leon & Claire | E7: × | F7: EXEMPLE - à supprimer | G7: =IF(D7="","",IFERROR(VALUE(LEFT(D7,FIND(" |",D7&" |")-1)),"?")) -> 3 | H7: =IF(G7="","",IF(G7="?","⚠ pub inconnue",IFERROR(INDEX(Pubs!$B$2:$B$3001,MATCH(G7,Pubs!$A$2:$A$3001,0))&"","⚠ pub inconnue"))) -> Biohazard 2 | I7: =IF(OR(G7="",G7="?"),"",IFERROR(INDEX(Pubs!$C$2:$C$3001,MATCH(G7,Pubs!$A$2:$A$3001,0))&"","")) -> PlayStation | J7: =IF(OR(G7="",G7="?"),"",IFERROR(INDEX(Pubs!$G$2:$G$3001,MATCH(G7,Pubs!$A$2:$A$3001,0))&"","")) -> Biohazard | K7: =IF(OR(G7="",G7="?"),"",IFERROR(INDEX(Pubs!$E$2:$E$3001,MATCH(G7,Pubs!$A$2:$A$3001,0)),"")) -> 2 | L7: =IF(A7="","",IFERROR(1/(1/INDEX(Numéros!$C$2:$C$3001,MATCH(A7&"|"&B7,Numéros!$F$2:$F$3001,0))),"")) -> 35440 | M7: =IF(OR(G7="",G7="?"),"",IFERROR(INDEX(Pubs!$D$2:$D$3001,MATCH(G7,Pubs!$A$2:$A$3001,0))&"","")) -> Leon & Claire | N7: =N(N6)+IF(AND(A7<>"",OR(Recherche!$C$4="",A7=Recherche!$C$4),OR(Recherche!$C$5="",B7&""=Recherche!$C$5&""),OR(Recherche!$C$6="",IFERROR(YEAR(L7),0)=Recherche!$C$6),OR(Recherche!$C$7="",ISNUMBER(SEARCH(Recherche!$C$7,H7))),OR(Recherche!$C$8="",J7=Recherche!$C$8),OR(Recherche!$C$9="",I7=Recherche!$C$9),OR(Recherche!$C$10="",G7&""=Recherche!$C$10&""),OR(Recherche!$C$11="",E7=Recherche!$C$11),OR(Recherche!$C$12="",ISNUMBER(SEARCH(Recherche!$C$12,M7&" "&F7)))),1,0) -> 6
A8: Sega Saturn Magazine | B8: 5 | C8: 1 | D8: 4 | Sakura Taisen (Sega Saturn) - Sakura au sabre | E8: ○ | F8: EXEMPLE - à supprimer | G8: =IF(D8="","",IFERROR(VALUE(LEFT(D8,FIND(" |",D8&" |")-1)),"?")) -> 4 | H8: =IF(G8="","",IF(G8="?","⚠ pub inconnue",IFERROR(INDEX(Pubs!$B$2:$B$3001,MATCH(G8,Pubs!$A$2:$A$3001,0))&"","⚠ pub inconnue"))) -> Sakura Taisen | I8: =IF(OR(G8="",G8="?"),"",IFERROR(INDEX(Pubs!$C$2:$C$3001,MATCH(G8,Pubs!$A$2:$A$3001,0))&"","")) -> Sega Saturn | J8: =IF(OR(G8="",G8="?"),"",IFERROR(INDEX(Pubs!$G$2:$G$3001,MATCH(G8,Pubs!$A$2:$A$3001,0))&"","")) -> Sakura Taisen | K8: =IF(OR(G8="",G8="?"),"",IFERROR(INDEX(Pubs!$E$2:$E$3001,MATCH(G8,Pubs!$A$2:$A$3001,0)),"")) -> 1 | L8: =IF(A8="","",IFERROR(1/(1/INDEX(Numéros!$C$2:$C$3001,MATCH(A8&"|"&B8,Numéros!$F$2:$F$3001,0))),"")) -> 35309 | M8: =IF(OR(G8="",G8="?"),"",IFERROR(INDEX(Pubs!$D$2:$D$3001,MATCH(G8,Pubs!$A$2:$A$3001,0))&"","")) -> Sakura au sabre | N8: =N(N7)+IF(AND(A8<>"",OR(Recherche!$C$4="",A8=Recherche!$C$4),OR(Recherche!$C$5="",B8&""=Recherche!$C$5&""),OR(Recherche!$C$6="",IFERROR(YEAR(L8),0)=Recherche!$C$6),OR(Recherche!$C$7="",ISNUMBER(SEARCH(Recherche!$C$7,H8))),OR(Recherche!$C$8="",J8=Recherche!$C$8),OR(Recherche!$C$9="",I8=Recherche!$C$9),OR(Recherche!$C$10="",G8&""=Recherche!$C$10&""),OR(Recherche!$C$11="",E8=Recherche!$C$11),OR(Recherche!$C$12="",ISNUMBER(SEARCH(Recherche!$C$12,M8&" "&F8)))),1,0) -> 7
A9: Weekly Famitsu | B9: 600 | C9: 4 | D9: 5 | Dragon Quest VII (PlayStation) - Logo + illustration | E9: × | F9: EXEMPLE - à supprimer | G9: =IF(D9="","",IFERROR(VALUE(LEFT(D9,FIND(" |",D9&" |")-1)),"?")) -> 5 | H9: =IF(G9="","",IF(G9="?","⚠ pub inconnue",IFERROR(INDEX(Pubs!$B$2:$B$3001,MATCH(G9,Pubs!$A$2:$A$3001,0))&"","⚠ pub inconnue"))) -> Dragon Quest VII | I9: =IF(OR(G9="",G9="?"),"",IFERROR(INDEX(Pubs!$C$2:$C$3001,MATCH(G9,Pubs!$A$2:$A$3001,0))&"","")) -> PlayStation | J9: =IF(OR(G9="",G9="?"),"",IFERROR(INDEX(Pubs!$G$2:$G$3001,MATCH(G9,Pubs!$A$2:$A$3001,0))&"","")) -> Dragon Quest | K9: =IF(OR(G9="",G9="?"),"",IFERROR(INDEX(Pubs!$E$2:$E$3001,MATCH(G9,Pubs!$A$2:$A$3001,0)),"")) -> 2 | L9: =IF(A9="","",IFERROR(1/(1/INDEX(Numéros!$C$2:$C$3001,MATCH(A9&"|"&B9,Numéros!$F$2:$F$3001,0))),"")) | M9: =IF(OR(G9="",G9="?"),"",IFERROR(INDEX(Pubs!$D$2:$D$3001,MATCH(G9,Pubs!$A$2:$A$3001,0))&"","")) -> Logo + illustration | N9: =N(N8)+IF(AND(A9<>"",OR(Recherche!$C$4="",A9=Recherche!$C$4),OR(Recherche!$C$5="",B9&""=Recherche!$C$5&""),OR(Recherche!$C$6="",IFERROR(YEAR(L9),0)=Recherche!$C$6),OR(Recherche!$C$7="",ISNUMBER(SEARCH(Recherche!$C$7,H9))),OR(Recherche!$C$8="",J9=Recherche!$C$8),OR(Recherche!$C$9="",I9=Recherche!$C$9),OR(Recherche!$C$10="",G9&""=Recherche!$C$10&""),OR(Recherche!$C$11="",E9=Recherche!$C$11),OR(Recherche!$C$12="",ISNUMBER(SEARCH(Recherche!$C$12,M9&" "&F9)))),1,0) -> 8
G10: =IF(D10="","",IFERROR(VALUE(LEFT(D10,FIND(" |",D10&" |")-1)),"?")) | H10: =IF(G10="","",IF(G10="?","⚠ pub inconnue",IFERROR(INDEX(Pubs!$B$2:$B$3001,MATCH(G10,Pubs!$A$2:$A$3001,0))&"","⚠ pub inconnue"))) | I10: =IF(OR(G10="",G10="?"),"",IFERROR(INDEX(Pubs!$C$2:$C$3001,MATCH(G10,Pubs!$A$2:$A$3001,0))&"","")) | J10: =IF(OR(G10="",G10="?"),"",IFERROR(INDEX(Pubs!$G$2:$G$3001,MATCH(G10,Pubs!$A$2:$A$3001,0))&"","")) | K10: =IF(OR(G10="",G10="?"),"",IFERROR(INDEX(Pubs!$E$2:$E$3001,MATCH(G10,Pubs!$A$2:$A$3001,0)),"")) | L10: =IF(A10="","",IFERROR(1/(1/INDEX(Numéros!$C$2:$C$3001,MATCH(A10&"|"&B10,Numéros!$F$2:$F$3001,0))),"")) | M10: =IF(OR(G10="",G10="?"),"",IFERROR(INDEX(Pubs!$D$2:$D$3001,MATCH(G10,Pubs!$A$2:$A$3001,0))&"","")) | N10: =N(N9)+IF(AND(A10<>"",OR(Recherche!$C$4="",A10=Recherche!$C$4),OR(Recherche!$C$5="",B10&""=Recherche!$C$5&""),OR(Recherche!$C$6="",IFERROR(YEAR(L10),0)=Recherche!$C$6),OR(Recherche!$C$7="",ISNUMBER(SEARCH(Recherche!$C$7,H10))),OR(Recherche!$C$8="",J10=Recherche!$C$8),OR(Recherche!$C$9="",I10=Recherche!$C$9),OR(Recherche!$C$10="",G10&""=Recherche!$C$10&""),OR(Recherche!$C$11="",E10=Recherche!$C$11),OR(Recherche!$C$12="",ISNUMBER(SEARCH(Recherche!$C$12,M10&" "&F10)))),1,0) -> 8
G11: =IF(D11="","",IFERROR(VALUE(LEFT(D11,FIND(" |",D11&" |")-1)),"?")) | H11: =IF(G11="","",IF(G11="?","⚠ pub inconnue",IFERROR(INDEX(Pubs!$B$2:$B$3001,MATCH(G11,Pubs!$A$2:$A$3001,0))&"","⚠ pub inconnue"))) | I11: =IF(OR(G11="",G11="?"),"",IFERROR(INDEX(Pubs!$C$2:$C$3001,MATCH(G11,Pubs!$A$2:$A$3001,0))&"","")) | J11: =IF(OR(G11="",G11="?"),"",IFERROR(INDEX(Pubs!$G$2:$G$3001,MATCH(G11,Pubs!$A$2:$A$3001,0))&"","")) | K11: =IF(OR(G11="",G11="?"),"",IFERROR(INDEX(Pubs!$E$2:$E$3001,MATCH(G11,Pubs!$A$2:$A$3001,0)),"")) | L11: =IF(A11="","",IFERROR(1/(1/INDEX(Numéros!$C$2:$C$3001,MATCH(A11&"|"&B11,Numéros!$F$2:$F$3001,0))),"")) | M11: =IF(OR(G11="",G11="?"),"",IFERROR(INDEX(Pubs!$D$2:$D$3001,MATCH(G11,Pubs!$A$2:$A$3001,0))&"","")) | N11: =N(N10)+IF(AND(A11<>"",OR(Recherche!$C$4="",A11=Recherche!$C$4),OR(Recherche!$C$5="",B11&""=Recherche!$C$5&""),OR(Recherche!$C$6="",IFERROR(YEAR(L11),0)=Recherche!$C$6),OR(Recherche!$C$7="",ISNUMBER(SEARCH(Recherche!$C$7,H11))),OR(Recherche!$C$8="",J11=Recherche!$C$8),OR(Recherche!$C$9="",I11=Recherche!$C$9),OR(Recherche!$C$10="",G11&""=Recherche!$C$10&""),OR(Recherche!$C$11="",E11=Recherche!$C$11),OR(Recherche!$C$12="",ISNUMBER(SEARCH(Recherche!$C$12,M11&" "&F11)))),1,0) -> 8
G12: =IF(D12="","",IFERROR(VALUE(LEFT(D12,FIND(" |",D12&" |")-1)),"?")) | H12: =IF(G12="","",IF(G12="?","⚠ pub inconnue",IFERROR(INDEX(Pubs!$B$2:$B$3001,MATCH(G12,Pubs!$A$2:$A$3001,0))&"","⚠ pub inconnue"))) | I12: =IF(OR(G12="",G12="?"),"",IFERROR(INDEX(Pubs!$C$2:$C$3001,MATCH(G12,Pubs!$A$2:$A$3001,0))&"","")) | J12: =IF(OR(G12="",G12="?"),"",IFERROR(INDEX(Pubs!$G$2:$G$3001,MATCH(G12,Pubs!$A$2:$A$3001,0))&"","")) | K12: =IF(OR(G12="",G12="?"),"",IFERROR(INDEX(Pubs!$E$2:$E$3001,MATCH(G12,Pubs!$A$2:$A$3001,0)),"")) | L12: =IF(A12="","",IFERROR(1/(1/INDEX(Numéros!$C$2:$C$3001,MATCH(A12&"|"&B12,Numéros!$F$2:$F$3001,0))),"")) | M12: =IF(OR(G12="",G12="?"),"",IFERROR(INDEX(Pubs!$D$2:$D$3001,MATCH(G12,Pubs!$A$2:$A$3001,0))&"","")) | N12: =N(N11)+IF(AND(A12<>"",OR(Recherche!$C$4="",A12=Recherche!$C$4),OR(Recherche!$C$5="",B12&""=Recherche!$C$5&""),OR(Recherche!$C$6="",IFERROR(YEAR(L12),0)=Recherche!$C$6),OR(Recherche!$C$7="",ISNUMBER(SEARCH(Recherche!$C$7,H12))),OR(Recherche!$C$8="",J12=Recherche!$C$8),OR(Recherche!$C$9="",I12=Recherche!$C$9),OR(Recherche!$C$10="",G12&""=Recherche!$C$10&""),OR(Recherche!$C$11="",E12=Recherche!$C$11),OR(Recherche!$C$12="",ISNUMBER(SEARCH(Recherche!$C$12,M12&" "&F12)))),1,0) -> 8
G13: =IF(D13="","",IFERROR(VALUE(LEFT(D13,FIND(" |",D13&" |")-1)),"?")) | H13: =IF(G13="","",IF(G13="?","⚠ pub inconnue",IFERROR(INDEX(Pubs!$B$2:$B$3001,MATCH(G13,Pubs!$A$2:$A$3001,0))&"","⚠ pub inconnue"))) | I13: =IF(OR(G13="",G13="?"),"",IFERROR(INDEX(Pubs!$C$2:$C$3001,MATCH(G13,Pubs!$A$2:$A$3001,0))&"","")) | J13: =IF(OR(G13="",G13="?"),"",IFERROR(INDEX(Pubs!$G$2:$G$3001,MATCH(G13,Pubs!$A$2:$A$3001,0))&"","")) | K13: =IF(OR(G13="",G13="?"),"",IFERROR(INDEX(Pubs!$E$2:$E$3001,MATCH(G13,Pubs!$A$2:$A$3001,0)),"")) | L13: =IF(A13="","",IFERROR(1/(1/INDEX(Numéros!$C$2:$C$3001,MATCH(A13&"|"&B13,Numéros!$F$2:$F$3001,0))),"")) | M13: =IF(OR(G13="",G13="?"),"",IFERROR(INDEX(Pubs!$D$2:$D$3001,MATCH(G13,Pubs!$A$2:$A$3001,0))&"","")) | N13: =N(N12)+IF(AND(A13<>"",OR(Recherche!$C$4="",A13=Recherche!$C$4),OR(Recherche!$C$5="",B13&""=Recherche!$C$5&""),OR(Recherche!$C$6="",IFERROR(YEAR(L13),0)=Recherche!$C$6),OR(Recherche!$C$7="",ISNUMBER(SEARCH(Recherche!$C$7,H13))),OR(Recherche!$C$8="",J13=Recherche!$C$8),OR(Recherche!$C$9="",I13=Recherche!$C$9),OR(Recherche!$C$10="",G13&""=Recherche!$C$10&""),OR(Recherche!$C$11="",E13=Recherche!$C$11),OR(Recherche!$C$12="",ISNUMBER(SEARCH(Recherche!$C$12,M13&" "&F13)))),1,0) -> 8
G14: =IF(D14="","",IFERROR(VALUE(LEFT(D14,FIND(" |",D14&" |")-1)),"?")) | H14: =IF(G14="","",IF(G14="?","⚠ pub inconnue",IFERROR(INDEX(Pubs!$B$2:$B$3001,MATCH(G14,Pubs!$A$2:$A$3001,0))&"","⚠ pub inconnue"))) | I14: =IF(OR(G14="",G14="?"),"",IFERROR(INDEX(Pubs!$C$2:$C$3001,MATCH(G14,Pubs!$A$2:$A$3001,0))&"","")) | J14: =IF(OR(G14="",G14="?"),"",IFERROR(INDEX(Pubs!$G$2:$G$3001,MATCH(G14,Pubs!$A$2:$A$3001,0))&"","")) | K14: =IF(OR(G14="",G14="?"),"",IFERROR(INDEX(Pubs!$E$2:$E$3001,MATCH(G14,Pubs!$A$2:$A$3001,0)),"")) | L14: =IF(A14="","",IFERROR(1/(1/INDEX(Numéros!$C$2:$C$3001,MATCH(A14&"|"&B14,Numéros!$F$2:$F$3001,0))),"")) | M14: =IF(OR(G14="",G14="?"),"",IFERROR(INDEX(Pubs!$D$2:$D$3001,MATCH(G14,Pubs!$A$2:$A$3001,0))&"","")) | N14: =N(N13)+IF(AND(A14<>"",OR(Recherche!$C$4="",A14=Recherche!$C$4),OR(Recherche!$C$5="",B14&""=Recherche!$C$5&""),OR(Recherche!$C$6="",IFERROR(YEAR(L14),0)=Recherche!$C$6),OR(Recherche!$C$7="",ISNUMBER(SEARCH(Recherche!$C$7,H14))),OR(Recherche!$C$8="",J14=Recherche!$C$8),OR(Recherche!$C$9="",I14=Recherche!$C$9),OR(Recherche!$C$10="",G14&""=Recherche!$C$10&""),OR(Recherche!$C$11="",E14=Recherche!$C$11),OR(Recherche!$C$12="",ISNUMBER(SEARCH(Recherche!$C$12,M14&" "&F14)))),1,0) -> 8
G15: =IF(D15="","",IFERROR(VALUE(LEFT(D15,FIND(" |",D15&" |")-1)),"?")) | H15: =IF(G15="","",IF(G15="?","⚠ pub inconnue",IFERROR(INDEX(Pubs!$B$2:$B$3001,MATCH(G15,Pubs!$A$2:$A$3001,0))&"","⚠ pub inconnue"))) | I15: =IF(OR(G15="",G15="?"),"",IFERROR(INDEX(Pubs!$C$2:$C$3001,MATCH(G15,Pubs!$A$2:$A$3001,0))&"","")) | J15: =IF(OR(G15="",G15="?"),"",IFERROR(INDEX(Pubs!$G$2:$G$3001,MATCH(G15,Pubs!$A$2:$A$3001,0))&"","")) | K15: =IF(OR(G15="",G15="?"),"",IFERROR(INDEX(Pubs!$E$2:$E$3001,MATCH(G15,Pubs!$A$2:$A$3001,0)),"")) | L15: =IF(A15="","",IFERROR(1/(1/INDEX(Numéros!$C$2:$C$3001,MATCH(A15&"|"&B15,Numéros!$F$2:$F$3001,0))),"")) | M15: =IF(OR(G15="",G15="?"),"",IFERROR(INDEX(Pubs!$D$2:$D$3001,MATCH(G15,Pubs!$A$2:$A$3001,0))&"","")) | N15: =N(N14)+IF(AND(A15<>"",OR(Recherche!$C$4="",A15=Recherche!$C$4),OR(Recherche!$C$5="",B15&""=Recherche!$C$5&""),OR(Recherche!$C$6="",IFERROR(YEAR(L15),0)=Recherche!$C$6),OR(Recherche!$C$7="",ISNUMBER(SEARCH(Recherche!$C$7,H15))),OR(Recherche!$C$8="",J15=Recherche!$C$8),OR(Recherche!$C$9="",I15=Recherche!$C$9),OR(Recherche!$C$10="",G15&""=Recherche!$C$10&""),OR(Recherche!$C$11="",E15=Recherche!$C$11),OR(Recherche!$C$12="",ISNUMBER(SEARCH(Recherche!$C$12,M15&" "&F15)))),1,0) -> 8
G16: =IF(D16="","",IFERROR(VALUE(LEFT(D16,FIND(" |",D16&" |")-1)),"?")) | H16: =IF(G16="","",IF(G16="?","⚠ pub inconnue",IFERROR(INDEX(Pubs!$B$2:$B$3001,MATCH(G16,Pubs!$A$2:$A$3001,0))&"","⚠ pub inconnue"))) | I16: =IF(OR(G16="",G16="?"),"",IFERROR(INDEX(Pubs!$C$2:$C$3001,MATCH(G16,Pubs!$A$2:$A$3001,0))&"","")) | J16: =IF(OR(G16="",G16="?"),"",IFERROR(INDEX(Pubs!$G$2:$G$3001,MATCH(G16,Pubs!$A$2:$A$3001,0))&"","")) | K16: =IF(OR(G16="",G16="?"),"",IFERROR(INDEX(Pubs!$E$2:$E$3001,MATCH(G16,Pubs!$A$2:$A$3001,0)),"")) | L16: =IF(A16="","",IFERROR(1/(1/INDEX(Numéros!$C$2:$C$3001,MATCH(A16&"|"&B16,Numéros!$F$2:$F$3001,0))),"")) | M16: =IF(OR(G16="",G16="?"),"",IFERROR(INDEX(Pubs!$D$2:$D$3001,MATCH(G16,Pubs!$A$2:$A$3001,0))&"","")) | N16: =N(N15)+IF(AND(A16<>"",OR(Recherche!$C$4="",A16=Recherche!$C$4),OR(Recherche!$C$5="",B16&""=Recherche!$C$5&""),OR(Recherche!$C$6="",IFERROR(YEAR(L16),0)=Recherche!$C$6),OR(Recherche!$C$7="",ISNUMBER(SEARCH(Recherche!$C$7,H16))),OR(Recherche!$C$8="",J16=Recherche!$C$8),OR(Recherche!$C$9="",I16=Recherche!$C$9),OR(Recherche!$C$10="",G16&""=Recherche!$C$10&""),OR(Recherche!$C$11="",E16=Recherche!$C$11),OR(Recherche!$C$12="",ISNUMBER(SEARCH(Recherche!$C$12,M16&" "&F16)))),1,0) -> 8
G17: =IF(D17="","",IFERROR(VALUE(LEFT(D17,FIND(" |",D17&" |")-1)),"?")) | H17: =IF(G17="","",IF(G17="?","⚠ pub inconnue",IFERROR(INDEX(Pubs!$B$2:$B$3001,MATCH(G17,Pubs!$A$2:$A$3001,0))&"","⚠ pub inconnue"))) | I17: =IF(OR(G17="",G17="?"),"",IFERROR(INDEX(Pubs!$C$2:$C$3001,MATCH(G17,Pubs!$A$2:$A$3001,0))&"","")) | J17: =IF(OR(G17="",G17="?"),"",IFERROR(INDEX(Pubs!$G$2:$G$3001,MATCH(G17,Pubs!$A$2:$A$3001,0))&"","")) | K17: =IF(OR(G17="",G17="?"),"",IFERROR(INDEX(Pubs!$E$2:$E$3001,MATCH(G17,Pubs!$A$2:$A$3001,0)),"")) | L17: =IF(A17="","",IFERROR(1/(1/INDEX(Numéros!$C$2:$C$3001,MATCH(A17&"|"&B17,Numéros!$F$2:$F$3001,0))),"")) | M17: =IF(OR(G17="",G17="?"),"",IFERROR(INDEX(Pubs!$D$2:$D$3001,MATCH(G17,Pubs!$A$2:$A$3001,0))&"","")) | N17: =N(N16)+IF(AND(A17<>"",OR(Recherche!$C$4="",A17=Recherche!$C$4),OR(Recherche!$C$5="",B17&""=Recherche!$C$5&""),OR(Recherche!$C$6="",IFERROR(YEAR(L17),0)=Recherche!$C$6),OR(Recherche!$C$7="",ISNUMBER(SEARCH(Recherche!$C$7,H17))),OR(Recherche!$C$8="",J17=Recherche!$C$8),OR(Recherche!$C$9="",I17=Recherche!$C$9),OR(Recherche!$C$10="",G17&""=Recherche!$C$10&""),OR(Recherche!$C$11="",E17=Recherche!$C$11),OR(Recherche!$C$12="",ISNUMBER(SEARCH(Recherche!$C$12,M17&" "&F17)))),1,0) -> 8
G18: =IF(D18="","",IFERROR(VALUE(LEFT(D18,FIND(" |",D18&" |")-1)),"?")) | H18: =IF(G18="","",IF(G18="?","⚠ pub inconnue",IFERROR(INDEX(Pubs!$B$2:$B$3001,MATCH(G18,Pubs!$A$2:$A$3001,0))&"","⚠ pub inconnue"))) | I18: =IF(OR(G18="",G18="?"),"",IFERROR(INDEX(Pubs!$C$2:$C$3001,MATCH(G18,Pubs!$A$2:$A$3001,0))&"","")) | J18: =IF(OR(G18="",G18="?"),"",IFERROR(INDEX(Pubs!$G$2:$G$3001,MATCH(G18,Pubs!$A$2:$A$3001,0))&"","")) | K18: =IF(OR(G18="",G18="?"),"",IFERROR(INDEX(Pubs!$E$2:$E$3001,MATCH(G18,Pubs!$A$2:$A$3001,0)),"")) | L18: =IF(A18="","",IFERROR(1/(1/INDEX(Numéros!$C$2:$C$3001,MATCH(A18&"|"&B18,Numéros!$F$2:$F$3001,0))),"")) | M18: =IF(OR(G18="",G18="?"),"",IFERROR(INDEX(Pubs!$D$2:$D$3001,MATCH(G18,Pubs!$A$2:$A$3001,0))&"","")) | N18: =N(N17)+IF(AND(A18<>"",OR(Recherche!$C$4="",A18=Recherche!$C$4),OR(Recherche!$C$5="",B18&""=Recherche!$C$5&""),OR(Recherche!$C$6="",IFERROR(YEAR(L18),0)=Recherche!$C$6),OR(Recherche!$C$7="",ISNUMBER(SEARCH(Recherche!$C$7,H18))),OR(Recherche!$C$8="",J18=Recherche!$C$8),OR(Recherche!$C$9="",I18=Recherche!$C$9),OR(Recherche!$C$10="",G18&""=Recherche!$C$10&""),OR(Recherche!$C$11="",E18=Recherche!$C$11),OR(Recherche!$C$12="",ISNUMBER(SEARCH(Recherche!$C$12,M18&" "&F18)))),1,0) -> 8
G19: =IF(D19="","",IFERROR(VALUE(LEFT(D19,FIND(" |",D19&" |")-1)),"?")) | H19: =IF(G19="","",IF(G19="?","⚠ pub inconnue",IFERROR(INDEX(Pubs!$B$2:$B$3001,MATCH(G19,Pubs!$A$2:$A$3001,0))&"","⚠ pub inconnue"))) | I19: =IF(OR(G19="",G19="?"),"",IFERROR(INDEX(Pubs!$C$2:$C$3001,MATCH(G19,Pubs!$A$2:$A$3001,0))&"","")) | J19: =IF(OR(G19="",G19="?"),"",IFERROR(INDEX(Pubs!$G$2:$G$3001,MATCH(G19,Pubs!$A$2:$A$3001,0))&"","")) | K19: =IF(OR(G19="",G19="?"),"",IFERROR(INDEX(Pubs!$E$2:$E$3001,MATCH(G19,Pubs!$A$2:$A$3001,0)),"")) | L19: =IF(A19="","",IFERROR(1/(1/INDEX(Numéros!$C$2:$C$3001,MATCH(A19&"|"&B19,Numéros!$F$2:$F$3001,0))),"")) | M19: =IF(OR(G19="",G19="?"),"",IFERROR(INDEX(Pubs!$D$2:$D$3001,MATCH(G19,Pubs!$A$2:$A$3001,0))&"","")) | N19: =N(N18)+IF(AND(A19<>"",OR(Recherche!$C$4="",A19=Recherche!$C$4),OR(Recherche!$C$5="",B19&""=Recherche!$C$5&""),OR(Recherche!$C$6="",IFERROR(YEAR(L19),0)=Recherche!$C$6),OR(Recherche!$C$7="",ISNUMBER(SEARCH(Recherche!$C$7,H19))),OR(Recherche!$C$8="",J19=Recherche!$C$8),OR(Recherche!$C$9="",I19=Recherche!$C$9),OR(Recherche!$C$10="",G19&""=Recherche!$C$10&""),OR(Recherche!$C$11="",E19=Recherche!$C$11),OR(Recherche!$C$12="",ISNUMBER(SEARCH(Recherche!$C$12,M19&" "&F19)))),1,0) -> 8
G20: =IF(D20="","",IFERROR(VALUE(LEFT(D20,FIND(" |",D20&" |")-1)),"?")) | H20: =IF(G20="","",IF(G20="?","⚠ pub inconnue",IFERROR(INDEX(Pubs!$B$2:$B$3001,MATCH(G20,Pubs!$A$2:$A$3001,0))&"","⚠ pub inconnue"))) | I20: =IF(OR(G20="",G20="?"),"",IFERROR(INDEX(Pubs!$C$2:$C$3001,MATCH(G20,Pubs!$A$2:$A$3001,0))&"","")) | J20: =IF(OR(G20="",G20="?"),"",IFERROR(INDEX(Pubs!$G$2:$G$3001,MATCH(G20,Pubs!$A$2:$A$3001,0))&"","")) | K20: =IF(OR(G20="",G20="?"),"",IFERROR(INDEX(Pubs!$E$2:$E$3001,MATCH(G20,Pubs!$A$2:$A$3001,0)),"")) | L20: =IF(A20="","",IFERROR(1/(1/INDEX(Numéros!$C$2:$C$3001,MATCH(A20&"|"&B20,Numéros!$F$2:$F$3001,0))),"")) | M20: =IF(OR(G20="",G20="?"),"",IFERROR(INDEX(Pubs!$D$2:$D$3001,MATCH(G20,Pubs!$A$2:$A$3001,0))&"","")) | N20: =N(N19)+IF(AND(A20<>"",OR(Recherche!$C$4="",A20=Recherche!$C$4),OR(Recherche!$C$5="",B20&""=Recherche!$C$5&""),OR(Recherche!$C$6="",IFERROR(YEAR(L20),0)=Recherche!$C$6),OR(Recherche!$C$7="",ISNUMBER(SEARCH(Recherche!$C$7,H20))),OR(Recherche!$C$8="",J20=Recherche!$C$8),OR(Recherche!$C$9="",I20=Recherche!$C$9),OR(Recherche!$C$10="",G20&""=Recherche!$C$10&""),OR(Recherche!$C$11="",E20=Recherche!$C$11),OR(Recherche!$C$12="",ISNUMBER(SEARCH(Recherche!$C$12,M20&" "&F20)))),1,0) -> 8
G21: =IF(D21="","",IFERROR(VALUE(LEFT(D21,FIND(" |",D21&" |")-1)),"?")) | H21: =IF(G21="","",IF(G21="?","⚠ pub inconnue",IFERROR(INDEX(Pubs!$B$2:$B$3001,MATCH(G21,Pubs!$A$2:$A$3001,0))&"","⚠ pub inconnue"))) | I21: =IF(OR(G21="",G21="?"),"",IFERROR(INDEX(Pubs!$C$2:$C$3001,MATCH(G21,Pubs!$A$2:$A$3001,0))&"","")) | J21: =IF(OR(G21="",G21="?"),"",IFERROR(INDEX(Pubs!$G$2:$G$3001,MATCH(G21,Pubs!$A$2:$A$3001,0))&"","")) | K21: =IF(OR(G21="",G21="?"),"",IFERROR(INDEX(Pubs!$E$2:$E$3001,MATCH(G21,Pubs!$A$2:$A$3001,0)),"")) | L21: =IF(A21="","",IFERROR(1/(1/INDEX(Numéros!$C$2:$C$3001,MATCH(A21&"|"&B21,Numéros!$F$2:$F$3001,0))),"")) | M21: =IF(OR(G21="",G21="?"),"",IFERROR(INDEX(Pubs!$D$2:$D$3001,MATCH(G21,Pubs!$A$2:$A$3001,0))&"","")) | N21: =N(N20)+IF(AND(A21<>"",OR(Recherche!$C$4="",A21=Recherche!$C$4),OR(Recherche!$C$5="",B21&""=Recherche!$C$5&""),OR(Recherche!$C$6="",IFERROR(YEAR(L21),0)=Recherche!$C$6),OR(Recherche!$C$7="",ISNUMBER(SEARCH(Recherche!$C$7,H21))),OR(Recherche!$C$8="",J21=Recherche!$C$8),OR(Recherche!$C$9="",I21=Recherche!$C$9),OR(Recherche!$C$10="",G21&""=Recherche!$C$10&""),OR(Recherche!$C$11="",E21=Recherche!$C$11),OR(Recherche!$C$12="",ISNUMBER(SEARCH(Recherche!$C$12,M21&" "&F21)))),1,0) -> 8
